Watching for file changes with StatReloader
[25/Jan/2023 19:58:54] "GET / HTTP/1.1" 200 666
[25/Jan/2023 19:59:14] "GET / HTTP/1.1" 200 666
[25/Jan/2023 19:59:42] "GET / HTTP/1.1" 200 666
[25/Jan/2023 19:59:44] "GET / HTTP/1.1" 200 666
[25/Jan/2023 20:00:13] "GET / HTTP/1.1" 200 666
[25/Jan/2023 20:02:04] "GET / HTTP/1.1" 200 960
[25/Jan/2023 20:02:12] "GET / HTTP/1.1" 200 960
[25/Jan/2023 20:03:19] "GET / HTTP/1.1" 200 602
[25/Jan/2023 20:03:25] "GET / HTTP/1.1" 200 602
[25/Jan/2023 20:04:21] "GET / HTTP/1.1" 200 351
[25/Jan/2023 20:04:37] "GET / HTTP/1.1" 200 351
Internal Server Error: /
Traceback (most recent call last):
  File "/home/pi/.local/lib/python3.9/site-packages/django/core/handlers/exception.py", line 55, in inner
    response = get_response(request)
  File "/home/pi/.local/lib/python3.9/site-packages/django/core/handlers/base.py", line 197, in _get_response
    response = wrapped_callback(request, *callback_args, **callback_kwargs)
  File "/home/pi/projects/thesolar.website/django/the_solar_website/public_page/views.py", line 21, in index
    current = all_metrics[4]
IndexError: list index out of range
[25/Jan/2023 20:05:45] "GET / HTTP/1.1" 500 63542
Internal Server Error: /
Traceback (most recent call last):
  File "/home/pi/.local/lib/python3.9/site-packages/django/core/handlers/exception.py", line 55, in inner
    response = get_response(request)
  File "/home/pi/.local/lib/python3.9/site-packages/django/core/handlers/base.py", line 197, in _get_response
    response = wrapped_callback(request, *callback_args, **callback_kwargs)
  File "/home/pi/projects/thesolar.website/django/the_solar_website/public_page/views.py", line 21, in index
    current = all_metrics[4]
IndexError: list index out of range
[25/Jan/2023 20:06:14] "GET / HTTP/1.1" 500 63542
